Workbook

Sheet DRS
A1: Category | B1: Description | C1: Size | D1: Plant No. | E1: Flooring | F1: Walls | G1: Ceiling | H1: Fittings | I1: Mirror | J1: Washbasin | K1: Toilet | L1: Door | M1: Door keys | N1: Shower | O1: Lights | P1: Windows | Q1: Interior paint | R1: Exterior paint | S1: ACs | T1: Comments
A2: Cabins | B2: Toilet Shower | C2: 32' | D2: DR.2.T.32.3 | E2: TRUE | F2: TRUE | G2: TRUE | H2: TRUE | I2: TRUE | J2: TRUE | K2: TRUE | L2: TRUE | M2: TRUE | N2: TRUE | O2: TRUE | P2: TRUE | Q2: TRUE | R2: TRUE | S2: TRUE | T2: [2026-05-15] Revising/ Checked by Calo | By: Calo
A3: Cabins | B3: Toilet | C3: 32' | D3: DR.2.T.32.8 | E3: TRUE | F3: TRUE | G3: TRUE | H3: TRUE | I3: TRUE | J3: TRUE | K3: TRUE | L3: TRUE | M3: TRUE | N3: TRUE | O3: TRUE | P3: TRUE | Q3: TRUE | R3: TRUE | S3: TRUE | T3: [2026-05-15] Revising/ Checked by Calo - testing archive feature | By: Calo
A4: Cabins | B4: Toilet | C4: 32' | D4: DR.2.T.32.9 | E4: TRUE | F4: TRUE | G4: TRUE | H4: TRUE | I4: TRUE | J4: TRUE | K4: TRUE | L4: TRUE | M4: TRUE | N4: TRUE | O4: TRUE | P4: TRUE | Q4: TRUE | R4: TRUE | S4: TRUE | T4: [2026-05-15] Revising/ Checked by Calo - testing archive feature | By: Calo
A5: Cabins | B5: Toilet Shower | C5: 32' | D5: DR.2.TS.32.1 | E5: TRUE | F5: TRUE | G5: TRUE | H5: TRUE | I5: TRUE | J5: TRUE | K5: TRUE | L5: TRUE | M5: TRUE | N5: TRUE | O5: TRUE | P5: TRUE | Q5: TRUE | R5: TRUE | S5: TRUE | T5: [2026-05-15] Revising/ Checked by Calo - testing archive feature | By: Calo
A6: Cabins | B6: Toilet Shower | C6: 32' | D6: DR.2.TS.32.2 | E6: FALSE | F6: FALSE | G6: FALSE | H6: FALSE | I6: FALSE | J6: FALSE | K6: FALSE | L6: FALSE | M6: FALSE | N6: FALSE | O6: FALSE | P6: FALSE | Q6: FALSE | R6: FALSE | S6: FALSE | T6: No inspection
A7: Cabins | B7: Toilet Shower | C7: 32' | D7: DR.2.TS.32.3 | E7: TRUE | F7: TRUE | G7: TRUE | H7: TRUE | I7: TRUE | J7: TRUE | K7: TRUE | L7: TRUE | M7: TRUE | N7: TRUE | O7: TRUE | P7: TRUE | Q7: TRUE | R7: TRUE | S7: TRUE | T7: [2026-05-15] Revising/ Checked by Calo - testing archive feature | By: Calo
A8: Cabins | B8: Toilet Shower | C8: 32' | D8: DR.2.TS.32.4 | E8: TRUE | F8: TRUE | G8: TRUE | H8: TRUE | I8: TRUE | J8: TRUE | K8: TRUE | L8: TRUE | M8: TRUE | N8: TRUE | O8: TRUE | P8: TRUE | Q8: TRUE | R8: TRUE | S8: TRUE | T8: [2026-04-16] We remove the Branding plate . Before Deliver time we fix Before deliver we fix Barinding plate | By: calo.lategan@allaith.com
A9: Cabins | B9: Toilet Shower | C9: 32' | D9: DR.2.TS.32.5 | E9: TRUE | F9: TRUE | G9: TRUE | H9: TRUE | I9: TRUE | J9: TRUE | K9: TRUE | L9: TRUE | M9: TRUE | N9: TRUE | O9: TRUE | P9: TRUE | Q9: TRUE | R9: TRUE | S9: TRUE | T9: [2026-05-15] Revising/ Checked by Calo - testing archive feature | By: Calo
A10: Cabins | B10: Toilet Shower | C10: 32' | D10: DR.2.TS.32.6 | E10: TRUE | F10: TRUE | G10: TRUE | H10: TRUE | I10: TRUE | J10: TRUE | K10: TRUE | L10: TRUE | M10: TRUE | N10: TRUE | O10: TRUE | P10: TRUE | Q10: TRUE | R10: TRUE | S10: TRUE | T10: [2026-05-15] Revising/ Checked by Calo - testing archive feature | By: Calo
A11: Cabins | B11: Toilet | C11: 40' | D11: DR.2T.40.01 | E11: TRUE | F11: TRUE | G11: TRUE | H11: TRUE | I11: TRUE | J11: TRUE | K11: TRUE | L11: TRUE | M11: TRUE | N11: TRUE | O11: TRUE | P11: TRUE | Q11: TRUE | R11: FALSE | S11: TRUE | T11: [2026-04-07] Before sent we will paint work finished within a day Extrior painting work before we will finished | By: calo.lategan@allaith.com | Defects: Exterior paint
A12: Cabins | B12: Toilet | C12: 40' | D12: DR.2T.40.02 | E12: TRUE | F12: TRUE | G12: TRUE | H12: TRUE | I12: TRUE | J12: TRUE | K12: TRUE | L12: TRUE | M12: TRUE | N12: TRUE | O12: TRUE | P12: N/A | Q12: TRUE | R12: FALSE | S12: TRUE | T12: [2026-05-15] Before sent we will paint within a day Extrior painting | By: calo.lategan@allaith.com | Defects: Exterior paint
A13: Cabins | B13: Toilet | C13: 40' | D13: DR.2.40.1 | E13: TRUE | F13: TRUE | G13: TRUE | H13: N/A | I13: N/A | J13: N/A | K13: N/A | L13: FALSE | M13: TRUE | N13: N/A | O13: TRUE | P13: N/A | Q13: TRUE | R13: FALSE | S13: TRUE | T13: [2026-04-16] Before deliver we will paint / branding we will fix before deliver door inside plywood need to change door inside plywood need to change 18/04 | By: calo.lategan@allaith.com | Defects: Door, Exterior paint

Sheet Shower unit
A1: Category | B1: Description | C1: Size | D1: Plant No. | E1: Flooring | F1: Walls | G1: Ceiling | H1: Fittings | I1: Mirror | J1: Washbasin | K1: Lights | L1: Shower | M1: Shower Curtain | N1: AC | O1: Door | P1: Electrical | Q1: WC | R1: Intrior paint | S1: exterior paint | T1: STATUS
A2: Cabins | B2: Shower | C2: 20' | D2: SHC.F.20.1 | E2: FALSE | F2: FALSE | G2: FALSE | H2: FALSE | I2: FALSE | J2: FALSE | K2: FALSE | L2: FALSE | M2: FALSE | N2: FALSE | O2: FALSE | P2: FALSE | Q2: FALSE | R2: FALSE | S2: FALSE | T2: No inspection
A3: Cabins | B3: Shower | C3: 20' | D3: SHC.M.20..1 | E3: FALSE | F3: FALSE | G3: FALSE | H3: FALSE | I3: FALSE | J3: FALSE | K3: FALSE | L3: FALSE | M3: FALSE | N3: FALSE | O3: FALSE | P3: FALSE | Q3: FALSE | R3: FALSE | S3: FALSE | T3: Top
A4: Cabins | B4: Shower | C4: 20' | D4: SHC.20.3 | E4: FALSE | F4: FALSE | G4: FALSE | H4: FALSE | I4: FALSE | J4: FALSE | K4: FALSE | L4: FALSE | M4: FALSE | N4: FALSE | O4: FALSE | P4: FALSE | Q4: FALSE | R4: FALSE | S4: FALSE | T4: No inspection
A5: Cabins | B5: Shower | C5: 20' | D5: SHC.20.4 | E5: FALSE | F5: FALSE | G5: FALSE | H5: FALSE | I5: FALSE | J5: FALSE | K5: FALSE | L5: FALSE | M5: FALSE | N5: FALSE | O5: FALSE | P5: FALSE | Q5: FALSE | R5: FALSE | S5: FALSE | T5: Top
A6: Cabins | B6: Shower | C6: 20' | D6: SHC.20.5 | E6: FALSE | F6: FALSE | G6: FALSE | H6: FALSE | I6: FALSE | J6: FALSE | K6: FALSE | L6: FALSE | M6: FALSE | N6: FALSE | O6: FALSE | P6: FALSE | Q6: FALSE | R6: FALSE | S6: FALSE | T6: No inspection

Sheet Ablution
A1: Category | B1: Description | C1: Size | D1: Plant No. | E1: Flooring | F1: Walls | G1: Ceiling | H1: Window | I1: WC | J1: Urinal | K1: Interior paint | L1: exterior paint | M1: Mirror | N1: Washbasin | O1: Lights | P1: Exhaust Fan | Q1: Door | R1: Door keys | S1: Comments
A2: Ablution | B2: VIP | C2: 32' | D2: VIPABLM-F.32.1 | E2: TRUE | F2: TRUE | G2: TRUE | H2: N/A | I2: TRUE | J2: TRUE | K2: TRUE | L2: TRUE | M2: TRUE | N2: TRUE | O2: TRUE | P2: TRUE | Q2: TRUE | R2: TRUE | S2: [2026-05-20] Inspection Done By ANTO | By: ANTO
A3: Ablution | B3: VIP | C3: 32' | D3: VIPABLM-F.32.2 | E3: TRUE | F3: TRUE | G3: TRUE | H3: N/A | I3: TRUE | J3: TRUE | K3: TRUE | L3: TRUE | M3: TRUE | N3: TRUE | O3: TRUE | P3: TRUE | Q3: TRUE | R3: TRUE | S3: [2026-05-20] Inspection Done By ANTO | By: ANTO
A4: Ablution | B4: POD | C4: 10' | D4: D.ABL.10.2 | E4: FALSE | F4: FALSE | G4: FALSE | H4: FALSE | I4: FALSE | J4: FALSE | K4: FALSE | L4: FALSE | M4: FALSE | N4: FALSE | O4: FALSE | P4: FALSE | Q4: FALSE | R4: FALSE | S4: No inspection
A5: Ablution | B5: POD | C5: 10' | D5: D.ABL.10.5 | E5: FALSE | F5: FALSE | G5: FALSE | H5: FALSE | I5: FALSE | J5: FALSE | K5: FALSE | L5: FALSE | M5: FALSE | N5: FALSE | O5: FALSE | P5: FALSE | Q5: FALSE | R5: FALSE | S5: No inspection
A6: Ablution | B6: POD VIP | C6: 10' | D6: D.ABL.10.3 | E6: FALSE | F6: FALSE | G6: FALSE | H6: FALSE | I6: FALSE | J6: FALSE | K6: FALSE | L6: FALSE | M6: FALSE | N6: FALSE | O6: FALSE | P6: FALSE | Q6: FALSE | R6: FALSE | S6: No inspection
A7: Ablution | B7: 4 Door VIP | C7: 16' | D7: 4DR.ABL.16.1 | E7: FALSE | F7: FALSE | G7: FALSE | H7: FALSE | I7: FALSE | J7: FALSE | K7: FALSE | L7: FALSE | M7: FALSE | N7: FALSE | O7: FALSE | P7: FALSE | Q7: FALSE | R7: FALSE | S7: No inspection
A8: Ablution | B8: 4 Door VIP | C8: 16' | D8: 4DR.ABL.16.2 | E8: FALSE | F8: FALSE | G8: FALSE | H8: FALSE | I8: FALSE | J8: FALSE | K8: FALSE | L8: FALSE | M8: FALSE | N8: FALSE | O8: FALSE | P8: FALSE | Q8: FALSE | R8: FALSE | S8: No inspection
A9: Ablution | B9: 4 Door VIP | C9: 16' | D9: 4DR.ABL.16.3 | E9: FALSE | F9: FALSE | G9: FALSE | H9: FALSE | I9: FALSE | J9: FALSE | K9: FALSE | L9: FALSE | M9: FALSE | N9: FALSE | O9: FALSE | P9: FALSE | Q9: FALSE | R9: FALSE | S9: No inspection
A10: Ablution | B10: 4 Door | C10: 20' | D10: 4DR.ABL.20.1 | E10: FALSE | F10: FALSE | G10: FALSE | H10: FALSE | I10: FALSE | J10: FALSE | K10: FALSE | L10: FALSE | M10: FALSE | N10: FALSE | O10: FALSE | P10: FALSE | Q10: FALSE | R10: FALSE | S10: No inspection
A11: Ablution | B11: 4 Door | C11: 20' | D11: 4DR.ABL.20.2 | E11: FALSE | F11: FALSE | G11: FALSE | H11: FALSE | I11: FALSE | J11: FALSE | K11: FALSE | L11: FALSE | M11: FALSE | N11: FALSE | O11: FALSE | P11: FALSE | Q11: FALSE | R11: FALSE | S11: No inspection
A12: Ablution | B12: 4 Door | C12: 20' | D12: 4DR.ABL.20.3 | E12: FALSE | F12: FALSE | G12: FALSE | H12: FALSE | I12: FALSE | J12: FALSE | K12: FALSE | L12: FALSE | M12: FALSE | N12: FALSE | O12: FALSE | P12: FALSE | Q12: FALSE | R12: FALSE | S12: No inspection
A13: Ablution | B13: 1+1 door | C13: 10'' | D13: ABL.10.2 | E13: FALSE | F13: FALSE | G13: FALSE | H13: FALSE | I13: FALSE | J13: FALSE | K13: FALSE | L13: FALSE | M13: FALSE | N13: FALSE | O13: FALSE | P13: FALSE | Q13: FALSE | R13: FALSE | S13: No inspection
A14: Ablution | B14: Female | C14: 20' | D14: ABL.F.20.11 | E14: FALSE | F14: FALSE | G14: FALSE | H14: FALSE | I14: FALSE | J14: FALSE | K14: FALSE | L14: FALSE | M14: FALSE | N14: FALSE | O14: FALSE | P14: FALSE | Q14: FALSE | R14: FALSE | S14: No inspection
A15: Ablution | B15: Female | C15: 20' | D15: ABL.F.20.3 | E15: FALSE | F15: FALSE | G15: FALSE | H15: FALSE | I15: FALSE | J15: FALSE | K15: FALSE | L15: FALSE | M15: FALSE | N15: FALSE | O15: FALSE | P15: FALSE | Q15: FALSE | R15: FALSE | S15: No inspection
... A29: Ablution | B29: Mixed | C29: 20' | D29: ABL.M-F.20.12 | E29: FALSE | F29: FALSE | G29: FALSE | H29: FALSE | I29: FALSE | J29: FALSE | K29: FALSE | L29: FALSE | M29: FALSE | N29: FALSE | O29: FALSE | P29: FALSE | Q29: FALSE | R29: FALSE | S29: No inspection
A30: Ablution | B30: Mixed | C30: 20' | D30: ABL.M-F.20.13 | E30: FALSE | F30: FALSE | G30: FALSE | H30: x | I30: FALSE | J30: FALSE | K30: FALSE | L30: FALSE | M30: FALSE | N30: FALSE | O30: FALSE | P30: FALSE | Q30: FALSE | R30: FALSE | S30: Scrap
A31: Ablution | B31: Mixed | C31: 20' | D31: ABL.M-F.20.18 | E31: FALSE | F31: FALSE | G31: FALSE | H31: FALSE | I31: FALSE | J31: FALSE | K31: FALSE | L31: FALSE | M31: FALSE | N31: FALSE | O31: FALSE | P31: FALSE | Q31: FALSE | R31: FALSE | S31: No inspection
A32: Ablution | B32: Mixed | C32: 20' | D32: ABL.M-F.20.2 | E32: FALSE | F32: FALSE | G32: FALSE | H32: FALSE | I32: FALSE | J32: FALSE | K32: FALSE | L32: FALSE | M32: FALSE | N32: FALSE | O32: FALSE | P32: FALSE | Q32: FALSE | R32: FALSE | S32: No inspection
A33: Ablution | B33: Mixed | C33: 20' | D33: ABL.M-F.20.3 | E33: FALSE | F33: FALSE | G33: FALSE | H33: FALSE | I33: FALSE | J33: FALSE | K33: FALSE | L33: FALSE | M33: FALSE | N33: FALSE | O33: FALSE | P33: FALSE | Q33: FALSE | R33: FALSE | S33: No inspection
A34: Ablution | B34: Mixed | C34: 20' | D34: ABL.M-F.20.5 | E34: FALSE | F34: FALSE | G34: FALSE | H34: FALSE | I34: FALSE | J34: FALSE | K34: FALSE | L34: FALSE | M34: FALSE | N34: FALSE | O34: FALSE | P34: FALSE | Q34: FALSE | R34: FALSE | S34: No inspection
A35: Ablution | B35: Mixed | C35: 20' | D35: ABL.M-F.20.4 | E35: FALSE | F35: FALSE | G35: FALSE | H35: FALSE | I35: FALSE | J35: FALSE | K35: FALSE | L35: FALSE | M35: FALSE | N35: FALSE | O35: FALSE | P35: FALSE | Q35: FALSE | R35: FALSE | S35: No inspection
A36: Ablution | B36: Mixed | C36: 20' | D36: ABL.M-F.20.6 | E36: FALSE | F36: FALSE | G36: FALSE | H36: FALSE | I36: FALSE | J36: FALSE | K36: FALSE | L36: FALSE | M36: FALSE | N36: FALSE | O36: FALSE | P36: FALSE | Q36: FALSE | R36: FALSE | S36: No inspection
A37: Ablution | B37: Mixed | C37: 20' | D37: ABL.M-F.20.7 | E37: FALSE | F37: FALSE | G37: FALSE | H37: FALSE | I37: FALSE | J37: FALSE | K37: FALSE | L37: FALSE | M37: FALSE | N37: FALSE | O37: FALSE | P37: FALSE | Q37: FALSE | R37: FALSE | S37: No inspection
A38: Ablution | B38: Mixed | C38: 20' | D38: ABL.M-F.20.8 | E38: FALSE | F38: FALSE | G38: FALSE | H38: FALSE | I38: FALSE | J38: FALSE | K38: FALSE | L38: FALSE | M38: FALSE | N38: FALSE | O38: FALSE | P38: FALSE | Q38: FALSE | R38: FALSE | S38: No inspection
A39: Ablution | B39: Mixed VIP | C39: 20' | D39: ABL.M-F.20.16 | E39: TRUE | F39: TRUE | G39: TRUE | H39: N/A | I39: TRUE | J39: TRUE | K39: TRUE | L39: TRUE | M39: TRUE | N39: TRUE | O39: TRUE | P39: TRUE | Q39: TRUE | R39: TRUE | S39: [2026-04-18] Inspection done by Anto | By: Anto
A40: Ablution | B40: Mixed VIP | C40: 20' | D40: ABL.M-F.20.14 | E40: FALSE | F40: FALSE | G40: FALSE | H40: FALSE | I40: FALSE | J40: FALSE | K40: FALSE | L40: FALSE | M40: FALSE | N40: FALSE | O40: FALSE | P40: FALSE | Q40: FALSE | R40: FALSE | S40: No inspection
A41: Ablution | B41: Female | C41: 40' | D41: ABL.F.40.01 | E41: TRUE | F41: TRUE | G41: TRUE | H41: N/A | I41: TRUE | J41: N/A | K41: TRUE | L41: TRUE | M41: TRUE | N41: TRUE | O41: TRUE | P41: TRUE | Q41: TRUE | R41: TRUE | S41: [2026-05-15] Inspection done by ANTO | By: ANTO
A42: Ablution | B42: Female | C42: 40' | D42: ABL.F.40.02 | E42: TRUE | F42: TRUE | G42: TRUE | H42: N/A | I42: TRUE | J42: N/A | K42: TRUE | L42: TRUE | M42: TRUE | N42: TRUE | O42: TRUE | P42: TRUE | Q42: TRUE | R42: TRUE | S42: [2026-05-15] Inspection done by ANTO | By: ANTO
A43: Ablution | B43: Female | C43: 40' | D43: ABL.F.40.03 | E43: TRUE | F43: TRUE | G43: TRUE | H43: N/A | I43: TRUE | J43: N/A | K43: TRUE | L43: TRUE | M43: TRUE | N43: TRUE | O43: TRUE | P43: TRUE | Q43: TRUE | R43: TRUE | S43: [2026-05-15] Inspection done by ANTO | By: ANTO
A44: Ablution | B44: Female | C44: 40' | D44: ABL.F.40.04 | E44: FALSE | F44: FALSE | G44: FALSE | H44: FALSE | I44: FALSE | J44: FALSE | K44: FALSE | L44: FALSE | M44: FALSE | N44: FALSE | O44: FALSE | P44: FALSE | Q44: FALSE | R44: FALSE | S44: No inspection
A45: Ablution | B45: Female | C45: 40' | D45: ABL.F.40.05 | E45: FALSE | F45: FALSE | G45: FALSE | H45: FALSE | I45: FALSE | J45: FALSE | K45: FALSE | L45: FALSE | M45: FALSE | N45: FALSE | O45: FALSE | P45: FALSE | Q45: FALSE | R45: FALSE | S45: No inspection
A46: Ablution | B46: Female | C46: 40' | D46: ABL.F.40.06 | E46: FALSE | F46: FALSE | G46: FALSE | H46: FALSE | I46: FALSE | J46: FALSE | K46: FALSE | L46: FALSE | M46: FALSE | N46: FALSE | O46: FALSE | P46: FALSE | Q46: FALSE | R46: FALSE | S46: No inspection
A47: Ablution | B47: Female | C47: 40' | D47: ABL.F.40.07 | E47: FALSE | F47: FALSE | G47: FALSE | H47: FALSE | I47: FALSE | J47: FALSE | K47: FALSE | L47: FALSE | M47: FALSE | N47: FALSE | O47: FALSE | P47: FALSE | Q47: FALSE | R47: FALSE | S47: No inspection
A48: Ablution | B48: Male | C48: 40' | D48: ABL.M.40.01 | E48: TRUE | F48: TRUE | G48: TRUE | H48: N/A | I48: TRUE | J48: TRUE | K48: TRUE | L48: TRUE | M48: TRUE | N48: TRUE | O48: TRUE | P48: TRUE | Q48: TRUE | R48: TRUE | S48: [2026-05-16] Inspection done by ANTO | By: ANTO
A49: Ablution | B49: Male | C49: 40' | D49: ABL.M.40.02 | E49: TRUE | F49: TRUE | G49: TRUE | H49: N/A | I49: TRUE | J49: TRUE | K49: TRUE | L49: TRUE | M49: TRUE | N49: TRUE | O49: TRUE | P49: TRUE | Q49: TRUE | R49: TRUE | S49: [2026-05-16] Inspection done by ANTO | By: ANTO
A50: Ablution | B50: Mixed | C50: 40' | D50: ABL.M.40.03 | E50: FALSE | F50: FALSE | G50: FALSE | H50: FALSE | I50: FALSE | J50: FALSE | K50: FALSE | L50: FALSE | M50: FALSE | N50: FALSE | O50: FALSE | P50: FALSE | Q50: FALSE | R50: FALSE | S50: No inspection
A51: Ablution | B51: Male | C51: 40' | D51: ABL.M.40.04 | E51: FALSE | F51: FALSE | G51: FALSE | H51: FALSE | I51: FALSE | J51: FALSE | K51: FALSE | L51: FALSE | M51: FALSE | N51: FALSE | O51: FALSE | P51: FALSE | Q51: FALSE | R51: FALSE | S51: No inspection
A52: Ablution | B52: Male | C52: 40' | D52: ABL.M.40.05 | E52: FALSE | F52: FALSE | G52: FALSE | H52: FALSE | I52: FALSE | J52: FALSE | K52: FALSE | L52: FALSE | M52: FALSE | N52: FALSE | O52: FALSE | P52: FALSE | Q52: FALSE | R52: FALSE | S52: No inspection
A53: Ablution | B53: Male | C53: 40' | D53: ABL.M.40.06 | E53: FALSE | F53: FALSE | G53: FALSE | H53: FALSE | I53: FALSE | J53: FALSE | K53: FALSE | L53: FALSE | M53: FALSE | N53: FALSE | O53: FALSE | P53: FALSE | Q53: FALSE | R53: FALSE | S53: No inspection
...

Sheet _QCMirror
A1: SourceFileId | B1: SourceName | C1: MirrorFileId | D1: MirroredAt
A2: 1pmW6kVOF1gXwCMWSnFvjVsXc1wwtR7IJ | B2: DR.2T.40.01-260407 POST PDI.pdf | C2: 17yTBpApEObof039H1tDZKcMS9-WfAPgr | D2: 46120.576
A3: 1Ut_AKnRQHNzAg6oAEIhA7eEUm5T8msdZ | B3: DR.2.T.32.9-260407 POST PDI.pdf | C3: 1Edbln0dwIXOBPHLI-raySZh7SyjV3p8i | D3: 46120.576
A4: 10wgtWMM71YsZ2p-FdXzgCYDL6bVftOTJ | B4: ABL.F.40.01-260404 POST PDI.pdf | C4: 1Fzj5QWQdmc2UFetNfEC4ZyrHJOvAmDvT | D4: 46120.576
A5: 1lF8OUdmtYZ3Y5XomuCeWN0wcg_OGWeEg | B5: ABL.F.40.02-260404 POST PDI.pdf | C5: 1KMWMvXfPTYBB0qtkgX1qMu1SUA_h-8x1 | D5: 46120.576
A6: 12uezddCyChgWSN_4n9R54WbompodJrk6 | B6: DR.2.T.32.8-260404 POST PDI.pdf | C6: 1U7rrsmLh1EFqcUmOWCNDJkc_r2grL5tr | D6: 46120.576
A7: 1gf3oXR9214Qe4ZYHhNdtvdvmRZk349iw | B7: DR.2.T.32.3-260404 POST PDI.pdf | C7: 1vR6LpsFoanefFjBP6QgmdpMRdIjiUEDk | D7: 46120.576
A8: 1OrXNyANh70KCiuF8VR9BM4qJeuNIjM-p | B8: DR.2.TS.32.5-260404 POST PDI.pdf | C8: 18SMskUTkk-_RP2RL0yUU97TgudhwOXa6 | D8: 46120.576
A9: 12LP-HWNGxpxyeJVa5RbyMZMVYDnfQpDs | B9: DR.2.TS.32.6-260404 POST PDI.pdf | C9: 1BChRoLxwLSQhwEP3VAJSMjoofNZ0G-3q | D9: 46120.576
A10: 1sGUUG2GoG8McUIRzfUnRlkYw4wo9uZid | B10: PB-260403 POST PDI.pdf | C10: 1gz3TOp5jB3h10IQm6S6AfxEUNRwhiDYh | D10: 46120.576
A11: 1DsuGxHP4eDAaNRiv-ovtOI3EAp1PXcT4 | B11: STC.20.6-260331 POST PDI.pdf | C11: 1eLmqgojPmO8SPULZU9EVcby6iupd65F6 | D11: 46120.576
A12: 1dkP3ucjSBVqqxmnTp8dH_-i0C_yNjcLr | B12: STC.40.8-260331 POST PDI.pdf | C12: 1L0zaXAqQpRmk_T08IqhsfADzi-762ldc | D12: 46120.576
A13: 15q3LWUL0_xWx_pqsqRQ2HZz14WLI10rT | B13: STC.20.5-260331 POST PDI.pdf | C13: 1X8AMBe_IarLAvAGLydLKiFCN6OYbcUlD | D13: 46120.576
... A23: 1lKl9AVG9aIRVOUxLA3pz_bUQqJfLvr1o | B23: PL.59-260330 POST PDI.pdf | C23: 1KS8fgnpFVIus_JyIG-Cn7L_EiR-NYF0q | D23: 46120.577

Sheet Messhall
A1: Category | B1: Description | C1: Size | D1: Plant No. | E1: Flooring | F1: Walls | G1: Ceiling | H1: Fittings | I1: AC | J1: Window Tint | K1: Roof | L1: Lights | M1: Door | N1: Comments
A2: Cabins | B2: Mess | C2: 40' | D2: MH.40.1-E | E2: FALSE | F2: FALSE | G2: FALSE | H2: FALSE | I2: FALSE | J2: FALSE | K2: FALSE | L2: FALSE | M2: FALSE | N2: No inspection
A3: Cabins | B3: Mess | C3: 40' | D3: MH.40.4 | E3: FALSE | F3: FALSE | G3: FALSE | H3: FALSE | I3: FALSE | J3: FALSE | K3: FALSE | L3: FALSE | M3: FALSE | N3: No inspection
A4: Cabins | B4: Mess | C4: 40' | D4: MH.40.5 | E4: FALSE | F4: FALSE | G4: FALSE | H4: FALSE | I4: FALSE | J4: FALSE | K4: FALSE | L4: FALSE | M4: FALSE | N4: No inspection
A5: Cabins | B5: Mess | C5: 40' | D5: MH.40.10-E | E5: FALSE | F5: FALSE | G5: FALSE | H5: FALSE | I5: FALSE | J5: FALSE | K5: FALSE | L5: FALSE | M5: FALSE | N5: No inspection
A6: Cabins | B6: Mess | C6: 40' | D6: MH.40.11-E | E6: FALSE | F6: FALSE | G6: FALSE | H6: FALSE | I6: FALSE | J6: FALSE | K6: FALSE | L6: FALSE | M6: FALSE | N6: No inspection
A7: Cabins | B7: Mess | C7: 40' | D7: MH.40.12-E | E7: FALSE | F7: FALSE | G7: FALSE | H7: FALSE | I7: FALSE | J7: FALSE | K7: FALSE | L7: FALSE | M7: FALSE | N7: No inspection
A8: Cabins | B8: Mess | C8: 40' | D8: MH.40.16-E | E8: FALSE | F8: FALSE | G8: FALSE | H8: FALSE | I8: FALSE | J8: FALSE | K8: FALSE | L8: FALSE | M8: FALSE | N8: No inspection
A9: Cabins | B9: Mess | C9: 40' | D9: MH.40.22-E | E9: FALSE | F9: FALSE | G9: FALSE | H9: FALSE | I9: FALSE | J9: FALSE | K9: FALSE | L9: FALSE | M9: FALSE | N9: No inspection
A10: Cabins | B10: Mess | C10: 40' | D10: MH.40.27-E | E10: FALSE | F10: FALSE | G10: FALSE | H10: FALSE | I10: FALSE | J10: FALSE | K10: FALSE | L10: FALSE | M10: FALSE | N10: No inspection
A11: Cabins | B11: Mess | C11: 40' | D11: MH.40.28-E | E11: FALSE | F11: FALSE | G11: FALSE | H11: FALSE | I11: FALSE | J11: FALSE | K11: FALSE | L11: FALSE | M11: FALSE | N11: No inspection

Sheet Cabins
A1: Category | B1: Description | C1: Size | D1: Plant No. | E1: Flooring | F1: Walls | G1: Ceiling | H1: Interior paint | I1: Exterior paint | J1: AC | K1: Window | L1: Blinds | M1: Lights | N1: Door | O1: Door keys | P1: Comments
A2: Cabins | B2: Ticket | C2: 8' | D2: TB.10.10 | E2: FALSE | F2: FALSE | G2: FALSE | H2: FALSE | I2: FALSE | J2: FALSE | K2: FALSE | L2: FALSE | M2: FALSE | N2: FALSE | O2: FALSE | P2: No inspection
A3: Cabins | B3: Ticket | C3: 8' | D3: TB.10.11 | E3: FALSE | F3: FALSE | G3: FALSE | H3: FALSE | I3: FALSE | J3: FALSE | K3: FALSE | L3: FALSE | M3: FALSE | N3: FALSE | O3: FALSE | P3: No inspection
A4: Cabins | B4: Ticket | C4: 8' | D4: TB.10.12 | E4: FALSE | F4: FALSE | G4: FALSE | H4: FALSE | I4: FALSE | J4: FALSE | K4: FALSE | L4: FALSE | M4: FALSE | N4: FALSE | O4: FALSE | P4: No inspection
A5: Cabins | B5: Ticket | C5: 8' | D5: TB.10.13 | E5: FALSE | F5: FALSE | G5: FALSE | H5: FALSE | I5: FALSE | J5: FALSE | K5: FALSE | L5: FALSE | M5: FALSE | N5: FALSE | O5: FALSE | P5: No inspection
A6: Cabins | B6: Ticket | C6: 8' | D6: TB.10.4 | E6: FALSE | F6: FALSE | G6: FALSE | H6: FALSE | I6: FALSE | J6: FALSE | K6: FALSE | L6: FALSE | M6: FALSE | N6: FALSE | O6: FALSE | P6: No inspection
A7: Cabins | B7: Ticket | C7: 8' | D7: TB.10.5 | E7: FALSE | F7: FALSE | G7: FALSE | H7: FALSE | I7: FALSE | J7: FALSE | K7: FALSE | L7: FALSE | M7: FALSE | N7: FALSE | O7: FALSE | P7: No inspection
A8: Cabins | B8: Ticket | C8: 8' | D8: TB.10.6 | E8: FALSE | F8: FALSE | G8: FALSE | H8: FALSE | I8: FALSE | J8: FALSE | K8: FALSE | L8: FALSE | M8: FALSE | N8: FALSE | O8: FALSE | P8: No inspection
A9: Cabins | B9: Ticket | C9: 8' | D9: TB.10.7 | E9: FALSE | F9: FALSE | G9: FALSE | H9: FALSE | I9: FALSE | J9: FALSE | K9: FALSE | L9: FALSE | M9: FALSE | N9: FALSE | O9: FALSE | P9: No inspection
A10: Cabins | B10: Ticket | C10: 8' | D10: TB.10.8 | E10: FALSE | F10: FALSE | G10: FALSE | H10: FALSE | I10: FALSE | J10: FALSE | K10: FALSE | L10: FALSE | M10: FALSE | N10: FALSE | O10: FALSE | P10: No inspection
A11: Cabins | B11: Ticket | C11: 8' | D11: TB.10.9 | E11: FALSE | F11: FALSE | G11: FALSE | H11: FALSE | I11: FALSE | J11: FALSE | K11: FALSE | L11: FALSE | M11: FALSE | N11: FALSE | O11: FALSE | P11: No inspection
A12: Cabins | B12: Ticket | C12: 10' | D12: TB.10.1 | E12: FALSE | F12: FALSE | G12: FALSE | H12: FALSE | I12: FALSE | J12: FALSE | K12: FALSE | L12: FALSE | M12: FALSE | N12: FALSE | O12: FALSE | P12: No inspection
A13: Cabins | B13: Ticket | C13: 10' | D13: TB.10.2 | E13: FALSE | F13: FALSE | G13: FALSE | H13: FALSE | I13: FALSE | J13: FALSE | K13: FALSE | L13: FALSE | M13: FALSE | N13: FALSE | O13: FALSE | P13: No inspection
... A17: Cabins | B17: OPO | C17: 20' | D17: STC.20.4 | E17: FALSE | F17: FALSE | G17: FALSE | H17: FALSE | I17: FALSE | J17: FALSE | K17: FALSE | L17: FALSE | M17: FALSE | N17: FALSE | O17: FALSE | P17: No inspection
A18: Cabins | B18: Storage | C18: 20' | D18: STC.20.5 | E18: TRUE | F18: TRUE | G18: TRUE | H18: TRUE | I18: TRUE | J18: N/A | K18: N/A | L18: FALSE | M18: N/A | N18: TRUE | O18: FALSE | P18: [2026-03-31] Inspection done by khaild | By: khaild
A19: Cabins | B19: Storage | C19: 20' | D19: STC.20.6 | E19: TRUE | F19: TRUE | G19: TRUE | H19: TRUE | I19: TRUE | J19: N/A | K19: N/A | L19: FALSE | M19: N/A | N19: TRUE | O19: FALSE | P19: [2026-03-31] Inspection done by khalid | By: khalid
A20: Cabins | B20: OPO | C20: 20' | D20: OPO.20.16 | E20: FALSE | F20: FALSE | G20: FALSE | H20: FALSE | I20: FALSE | J20: FALSE | K20: FALSE | L20: FALSE | M20: FALSE | N20: FALSE | O20: FALSE | P20: No inspection
A21: Cabins | B21: OPO | C21: 20' | D21: OPO.20.01 | E21: FALSE | F21: FALSE | G21: FALSE | H21: FALSE | I21: FALSE | J21: FALSE | K21: FALSE | L21: FALSE | M21: FALSE | N21: FALSE | O21: FALSE | P21: No inspection
A22: Cabins | B22: OPO | C22: 20' | D22: OPO.20.10 | E22: FALSE | F22: FALSE | G22: FALSE | H22: FALSE | I22: FALSE | J22: FALSE | K22: FALSE | L22: FALSE | M22: FALSE | N22: FALSE | O22: FALSE | P22: No inspection
A23: Cabins | B23: OPO | C23: 20' | D23: OPO.20.11 | E23: FALSE | F23: FALSE | G23: FALSE | H23: FALSE | I23: FALSE | J23: FALSE | K23: FALSE | L23: FALSE | M23: FALSE | N23: FALSE | O23: FALSE | P23: No inspection
A24: Cabins | B24: OPO | C24: 20' | D24: OPO.20.12 | E24: FALSE | F24: FALSE | G24: FALSE | H24: FALSE | I24: FALSE | J24: FALSE | K24: FALSE | L24: FALSE | M24: FALSE | N24: FALSE | O24: FALSE | P24: No inspection
A25: Cabins | B25: OPO | C25: 20' | D25: OPO.20.17 | E25: FALSE | F25: FALSE | G25: FALSE | H25: FALSE | I25: FALSE | J25: FALSE | K25: FALSE | L25: FALSE | M25: FALSE | N25: FALSE | O25: FALSE | P25: No inspection
A26: Cabins | B26: OPO | C26: 20' | D26: OPO.20.13 | E26: FALSE | F26: FALSE | G26: FALSE | H26: FALSE | I26: FALSE | J26: FALSE | K26: FALSE | L26: FALSE | M26: FALSE | N26: FALSE | O26: FALSE | P26: No inspection
A27: Cabins | B27: OPO | C27: 20' | D27: OPO.20.18 | E27: FALSE | F27: FALSE | G27: FALSE | H27: FALSE | I27: FALSE | J27: FALSE | K27: FALSE | L27: FALSE | M27: FALSE | N27: FALSE | O27: FALSE | P27: No inspection
A28: Cabins | B28: OPO | C28: 20' | D28: OPO.20.02 | E28: FALSE | F28: FALSE | G28: FALSE | H28: FALSE | I28: FALSE | J28: FALSE | K28: FALSE | L28: FALSE | M28: FALSE | N28: FALSE | O28: FALSE | P28: No inspection
A29: Cabins | B29: OPO | C29: 20' | D29: OPO.20.23 | E29: FALSE | F29: FALSE | G29: FALSE | H29: FALSE | I29: FALSE | J29: FALSE | K29: FALSE | L29: FALSE | M29: FALSE | N29: FALSE | O29: FALSE | P29: No inspection
A30: Cabins | B30: OPO | C30: 20' | D30: OPO.20.24 | E30: FALSE | F30: FALSE | G30: FALSE | H30: FALSE | I30: FALSE | J30: FALSE | K30: FALSE | L30: FALSE | M30: FALSE | N30: FALSE | O30: FALSE | P30: No inspection
A31: Cabins | B31: OPO | C31: 20' | D31: OPO.20.25 | E31: TRUE | F31: TRUE | G31: TRUE | H31: FALSE | I31: FALSE | J31: TRUE | K31: TRUE | L31: TRUE | M31: TRUE | N31: TRUE | O31: TRUE | P31: [2026-06-05] By Calo | By: Calo | Defects: Interior paint, Exterior paint
... A41: Cabins | B41: OPO | C41: 20' | D41: OPO.20.06 | E41: FALSE | F41: FALSE | G41: FALSE | H41: FALSE | I41: FALSE | J41: FALSE | K41: FALSE | L41: FALSE | M41: FALSE | N41: FALSE | O41: FALSE | P41: No inspection
A42: Cabins | B42: OPO | C42: 20' | D42: OPO.20.07 | E42: TRUE | F42: TRUE | G42: TRUE | H42: FALSE | I42: FALSE | J42: FALSE | K42: TRUE | L42: N/A | M42: FALSE | N42: TRUE | O42: TRUE | P42: [2026-06-05] To clean, paint and do maintenance... 2 days work to 3 | By: calo.lategan@allaith.com | Defects: Interior paint, Exterior paint, AC, Lights
A43: Cabins | B43: OPO | C43: 24' | D43: OPO.24.1 | E43: FALSE | F43: FALSE | G43: FALSE | H43: FALSE | I43: FALSE | J43: FALSE | K43: FALSE | L43: FALSE | M43: FALSE | N43: FALSE | O43: FALSE | P43: No inspection
A44: Cabins | B44: OPO | C44: 30' | D44: OPO.30.1 | E44: FALSE | F44: FALSE | G44: FALSE | H44: FALSE | I44: FALSE | J44: FALSE | K44: FALSE | L44: FALSE | M44: FALSE | N44: FALSE | O44: FALSE | P44: No inspection
A45: Cabins | B45: OPO | C45: 30' | D45: OPO.30.3 | E45: FALSE | F45: FALSE | G45: FALSE | H45: FALSE | I45: FALSE | J45: FALSE | K45: FALSE | L45: FALSE | M45: FALSE | N45: FALSE | O45: FALSE | P45: No inspection
A46: Cabins | B46: OPO | C46: 30' | D46: OPO.30.4 | E46: FALSE | F46: FALSE | G46: FALSE | H46: FALSE | I46: FALSE | J46: FALSE | K46: FALSE | L46: FALSE | M46: FALSE | N46: FALSE | O46: FALSE | P46: No inspection
A47: Cabins | B47: OPO | C47: 30' | D47: OPO.30.5 | E47: FALSE | F47: FALSE | G47: FALSE | H47: FALSE | I47: FALSE | J47: FALSE | K47: FALSE | L47: FALSE | M47: FALSE | N47: FALSE | O47: FALSE | P47: No inspection
A48: Cabins | B48: OPO | C48: 30' | D48: OPO.30.6 | E48: FALSE | F48: FALSE | G48: FALSE | H48: FALSE | I48: FALSE | J48: FALSE | K48: FALSE | L48: FALSE | M48: FALSE | N48: FALSE | O48: FALSE | P48: No inspection
A49: Cabins | B49: OPO | C49: 32' | D49: OPO.32.1 | E49: FALSE | F49: FALSE | G49: FALSE | H49: FALSE | I49: FALSE | J49: FALSE | K49: FALSE | L49: FALSE | M49: FALSE | N49: FALSE | O49: FALSE | P49: No inspection
A50: Cabins | B50: OPO sound proof | C50: 40' | D50: OPO.40.4 | E50: TRUE | F50: TRUE | G50: TRUE | H50: TRUE | I50: TRUE | J50: TRUE | K50: N/A | L50: N/A | M50: TRUE | N50: TRUE | O50: TRUE | P50: [2026-05-20] Inspection Done By ANTO | By: ANTO
A51: Cabins | B51: OPO sound proof | C51: 40' | D51: OPO.40.7 | E51: FALSE | F51: FALSE | G51: FALSE | H51: FALSE | I51: FALSE | J51: FALSE | K51: FALSE | L51: FALSE | M51: FALSE | N51: FALSE | O51: FALSE | P51: No inspection
A52: Cabins | B52: OPO | C52: 40' | D52: OPO.40.1 | E52: FALSE | F52: FALSE | G52: FALSE | H52: FALSE | I52: FALSE | J52: FALSE | K52: FALSE | L52: FALSE | M52: FALSE | N52: FALSE | O52: FALSE | P52: No inspection
...

Sheet Flatpack
A1: Category | B1: Description | C1: Size | D1: Plant No. | E1: Flooring | F1: Walls | G1: Ceiling | H1: AC | I1: Lights | J1: Comments
A2: Containers | B2: Flatpack | C2: 16' flatpack | D2: F.P.O.20.1 | E2: FALSE | F2: FALSE | G2: FALSE | H2: FALSE | I2: FALSE | J2: No inspection
A3: Containers | B3: Flatpack | C3: 16' flatpack | D3: F.P.O.20.2 | E3: FALSE | F3: FALSE | G3: FALSE | H3: FALSE | I3: FALSE | J3: No inspection
A4: Containers | B4: Flatpack | C4: 16' flatpack | D4: F.P.O.20.3 | E4: FALSE | F4: FALSE | G4: FALSE | H4: FALSE | I4: FALSE | J4: No inspection
A5: Containers | B5: Flatpack | C5: 16' flatpack | D5: F.P.O.20.4 | E5: FALSE | F5: FALSE | G5: FALSE | H5: FALSE | I5: FALSE | J5: No inspection
A6: Containers | B6: Flatpack | C6: 16' flatpack | D6: F.P.O.20.5 | E6: FALSE | F6: FALSE | G6: FALSE | H6: FALSE | I6: FALSE | J6: No inspection

Sheet Flexiloo
A1: Category | B1: Description | C1: Size | D1: Plant No. | E1: Flooring | F1: Counter tops | G1: Lights | H1: Mirror | I1: Fittings | J1: Ceilings | K1: Walls | L1: Doors | M1: WC - urinal | N1: Basin | O1: Comments
A2: Sanitation | B2: Flexiloo EAWC | C2: EAWC | D2: FLX.EAWC.001 | E2: FALSE | F2: FALSE | G2: FALSE | H2: FALSE | I2: FALSE | J2: FALSE | K2: FALSE | L2: FALSE | M2: FALSE | N2: FALSE | O2: No inspection
A3: Sanitation | B3: Flexiloo EAWC | C3: EAWC | D3: FLX.EAWC.002 | E3: FALSE | F3: FALSE | G3: FALSE | H3: FALSE | I3: FALSE | J3: FALSE | K3: FALSE | L3: FALSE | M3: FALSE | N3: FALSE | O3: No inspection
A4: Sanitation | B4: Flexiloo EAWC | C4: EAWC | D4: FLX.EAWC.003 | E4: FALSE | F4: FALSE | G4: FALSE | H4: FALSE | I4: FALSE | J4: FALSE | K4: FALSE | L4: FALSE | M4: FALSE | N4: FALSE | O4: No inspection
A5: Sanitation | B5: Flexiloo EAWC | C5: EAWC | D5: FLX.EAWC.004 | E5: FALSE | F5: FALSE | G5: FALSE | H5: FALSE | I5: FALSE | J5: FALSE | K5: FALSE | L5: FALSE | M5: FALSE | N5: FALSE
A6: Sanitation | B6: Flexiloo Shower Cubicle | C6: Shower | D6: FLX.SHC.001 | E6: FALSE | F6: FALSE | G6: FALSE | H6: FALSE | I6: FALSE | J6: FALSE | K6: FALSE | L6: FALSE | M6: FALSE | N6: FALSE | O6: No inspection
A7: Sanitation | B7: Flexiloo Shower Cubicle | C7: Shower | D7: FLX.SHC.002 | E7: FALSE | F7: FALSE | G7: FALSE | H7: FALSE | I7: FALSE | J7: FALSE | K7: FALSE | L7: FALSE | M7: FALSE | N7: FALSE | O7: No inspection
A8: Sanitation | B8: Flexiloo Shower Cubicle | C8: Shower | D8: FLX.SHC.003 | E8: FALSE | F8: FALSE | G8: FALSE | H8: FALSE | I8: FALSE | J8: FALSE | K8: FALSE | L8: FALSE | M8: FALSE | N8: FALSE | O8: No inspection
A9: Sanitation | B9: Flexiloo Shower Cubicle | C9: Shower | D9: FLX.SHC.004 | E9: FALSE | F9: FALSE | G9: FALSE | H9: FALSE | I9: FALSE | J9: FALSE | K9: FALSE | L9: FALSE | M9: FALSE | N9: FALSE | O9: No inspection
A10: Sanitation | B10: Flexiloo Gent Urinal | C10: Urinal | D10: FLX.UR.004 | E10: FALSE | F10: FALSE | G10: FALSE | H10: FALSE | I10: FALSE | J10: FALSE | K10: FALSE | L10: FALSE | M10: FALSE | N10: FALSE | O10: No inspection
A11: Sanitation | B11: Flexiloo Gent Urinal | C11: Urinal | D11: FLX.UR.005 | E11: FALSE | F11: FALSE | G11: FALSE | H11: FALSE | I11: FALSE | J11: FALSE | K11: FALSE | L11: FALSE | M11: FALSE | N11: FALSE | O11: No inspection
A12: Sanitation | B12: Flexiloo Gent Urinal | C12: Urinal | D12: FLX.UR.006 | E12: FALSE | F12: FALSE | G12: FALSE | H12: FALSE | I12: FALSE | J12: FALSE | K12: FALSE | L12: FALSE | M12: FALSE | N12: FALSE | O12: No inspection
A13: Sanitation | B13: Flexiloo Gent Urinal | C13: Urinal | D13: FLX.UR.007 | E13: FALSE | F13: FALSE | G13: FALSE | H13: FALSE | I13: FALSE | J13: FALSE | K13: FALSE | L13: FALSE | M13: FALSE | N13: FALSE | O13: No inspection
A14: Sanitation | B14: Flexiloo Gent Urinal | C14: Urinal | D14: FLX.UR.008 | E14: FALSE | F14: FALSE | G14: FALSE | H14: FALSE | I14: FALSE | J14: FALSE | K14: FALSE | L14: FALSE | M14: FALSE | N14: FALSE | O14: No inspection
A15: Sanitation | B15: Flexiloo Gent Urinal | C15: Urinal | D15: FLX.UR.009 | E15: FALSE | F15: FALSE | G15: FALSE | H15: FALSE | I15: FALSE | J15: FALSE | K15: FALSE | L15: FALSE | M15: FALSE | N15: FALSE | O15: No inspection
A16: Sanitation | B16: Flexiloo Gent Urinal | C16: Urinal | D16: FLX.UR.010 | E16: FALSE | F16: FALSE | G16: FALSE | H16: FALSE | I16: FALSE | J16: FALSE | K16: FALSE | L16: FALSE | M16: FALSE | N16: FALSE | O16: No inspection
A17: Sanitation | B17: Flexiloo Gent Urinal | C17: Urinal | D17: FLX.UR.011 | E17: FALSE | F17: FALSE | G17: FALSE | H17: FALSE | I17: FALSE | J17: FALSE | K17: FALSE | L17: FALSE | M17: FALSE | N17: FALSE | O17: No inspection
... A166: Sanitation | B166: Flexiloo WC | C166: Toilet | D166: FLX.WC.32 | E166: FALSE | F166: FALSE | G166: FALSE | H166: FALSE | I166: FALSE | J166: FALSE | K166: FALSE | L166: FALSE | M166: FALSE | N166: FALSE | O166: No inspection
A167: Sanitation | B167: Flexiloo WC | C167: Toilet | D167: FLX.WC.33 | E167: TRUE | F167: N/A | G167: TRUE | H167: N/A | I167: TRUE | J167: TRUE | K167: TRUE | L167: TRUE | M167: TRUE | N167: N/A | O167: [2026-04-16] Inspection done by yadav | By: yadav
A168: Sanitation | B168: Flexiloo WC | C168: Toilet | D168: FLX.WC.34 | E168: FALSE | F168: FALSE | G168: FALSE | H168: FALSE | I168: FALSE | J168: FALSE | K168: FALSE | L168: FALSE | M168: FALSE | N168: FALSE | O168: No inspection
A169: Sanitation | B169: Flexiloo WC | C169: Toilet | D169: FLX.WC.35 | E169: FALSE | F169: FALSE | G169: FALSE | H169: FALSE | I169: FALSE | J169: FALSE | K169: FALSE | L169: FALSE | M169: FALSE | N169: FALSE | O169: No inspection
A170: Sanitation | B170: Flexiloo WC | C170: Toilet | D170: FLX.WC.36 | E170: FALSE | F170: FALSE | G170: FALSE | H170: FALSE | I170: FALSE | J170: FALSE | K170: FALSE | L170: FALSE | M170: FALSE | N170: FALSE | O170: No inspection
A171: Sanitation | B171: Flexiloo WC | C171: Toilet | D171: FLX.WC.37 | E171: FALSE | F171: FALSE | G171: FALSE | H171: FALSE | I171: FALSE | J171: FALSE | K171: FALSE | L171: FALSE | M171: FALSE | N171: FALSE | O171: No inspection
A172: Sanitation | B172: Flexiloo WC | C172: Toilet | D172: FLX.WC.38 | E172: FALSE | F172: FALSE | G172: FALSE | H172: FALSE | I172: FALSE | J172: FALSE | K172: FALSE | L172: FALSE | M172: FALSE | N172: FALSE | O172: No inspection
A173: Sanitation | B173: Flexiloo WC | C173: Toilet | D173: FLX.WC.39 | E173: FALSE | F173: FALSE | G173: FALSE | H173: FALSE | I173: FALSE | J173: FALSE | K173: FALSE | L173: FALSE | M173: FALSE | N173: FALSE | O173: No inspection
A174: Sanitation | B174: Flexiloo WC | C174: Toilet | D174: FLX.WC.40 | E174: FALSE | F174: FALSE | G174: FALSE | H174: FALSE | I174: FALSE | J174: FALSE | K174: FALSE | L174: FALSE | M174: FALSE | N174: FALSE | O174: No inspection
A175: Sanitation | B175: Flexiloo WC | C175: Toilet | D175: FLX.WC.41 | E175: FALSE | F175: FALSE | G175: FALSE | H175: FALSE | I175: FALSE | J175: FALSE | K175: FALSE | L175: FALSE | M175: FALSE | N175: FALSE | O175: No inspection
A176: Sanitation | B176: Flexiloo WC | C176: Toilet | D176: FLX.WC.42 | E176: FALSE | F176: FALSE | G176: FALSE | H176: FALSE | I176: FALSE | J176: FALSE | K176: FALSE | L176: FALSE | M176: FALSE | N176: FALSE | O176: No inspection
A177: Sanitation | B177: Flexiloo WC | C177: Toilet | D177: FLX.WC.43 | E177: FALSE | F177: FALSE | G177: FALSE | H177: FALSE | I177: FALSE | J177: FALSE | K177: FALSE | L177: FALSE | M177: FALSE | N177: FALSE | O177: No inspection
A178: Sanitation | B178: Flexiloo WC | C178: Toilet | D178: FLX.WC.44 | E178: FALSE | F178: FALSE | G178: FALSE | H178: FALSE | I178: FALSE | J178: FALSE | K178: FALSE | L178: FALSE | M178: FALSE | N178: FALSE | O178: No inspection
A179: Sanitation | B179: Flexiloo WC | C179: Toilet | D179: FLX.WC.45 | E179: FALSE | F179: FALSE | G179: FALSE | H179: FALSE | I179: FALSE | J179: FALSE | K179: FALSE | L179: FALSE | M179: FALSE | N179: FALSE | O179: No inspection
A180: Sanitation | B180: Flexiloo WC | C180: Toilet | D180: FLX.WC.46 | E180: TRUE | F180: FALSE | G180: TRUE | H180: N/A | I180: FALSE | J180: TRUE | K180: TRUE | L180: TRUE | M180: TRUE | N180: TRUE | O180: [2026-04-14] Inspection done yadav | By: calo.lategan@allaith.com
A181: Sanitation | B181: Flexiloo WC | C181: Toilet | D181: FLX.WC.47 | E181: TRUE | F181: FALSE | G181: TRUE | H181: N/A | I181: FALSE | J181: TRUE | K181: TRUE | L181: TRUE | M181: TRUE | N181: TRUE | O181: [2026-04-14] Inspection done by yadav | By: yadav
A182: Sanitation | B182: Flexiloo WC | C182: Toilet | D182: FLX.WC.48 | E182: FALSE | F182: FALSE | G182: FALSE | H182: FALSE | I182: FALSE | J182: FALSE | K182: FALSE | L182: FALSE | M182: FALSE | N182: FALSE | O182: No inspection
A183: Sanitation | B183: Flexiloo WC | C183: Toilet | D183: FLX.WC.49 | E183: FALSE | F183: FALSE | G183: FALSE | H183: FALSE | I183: FALSE | J183: FALSE | K183: FALSE | L183: FALSE | M183: FALSE | N183: FALSE | O183: No inspection
A184: Sanitation | B184: Flexiloo WC | C184: Toilet | D184: FLX.WC.50 | E184: FALSE | F184: FALSE | G184: FALSE | H184: FALSE | I184: FALSE | J184: FALSE | K184: FALSE | L184: FALSE | M184: FALSE | N184: FALSE | O184: No inspection
A185: Sanitation | B185: Flexiloo WC | C185: Toilet | D185: FLX.WC.51 | E185: FALSE | F185: FALSE | G185: FALSE | H185: FALSE | I185: FALSE | J185: FALSE | K185: FALSE | L185: FALSE | M185: FALSE | N185: FALSE | O185: No inspection
A186: Sanitation | B186: Flexiloo WC | C186: Toilet | D186: FLX.WC.52 | E186: FALSE | F186: FALSE | G186: FALSE | H186: FALSE | I186: FALSE | J186: FALSE | K186: FALSE | L186: FALSE | M186: FALSE | N186: FALSE | O186: No inspection
A187: Sanitation | B187: Flexiloo WC | C187: Toilet | D187: FLX.WC.53 | E187: FALSE | F187: FALSE | G187: FALSE | H187: FALSE | I187: FALSE | J187: FALSE | K187: FALSE | L187: FALSE | M187: FALSE | N187: FALSE | O187: No inspection
A188: Sanitation | B188: Flexiloo WC | C188: Toilet | D188: FLX.WC.54 | E188: FALSE | F188: FALSE | G188: FALSE | H188: FALSE | I188: FALSE | J188: FALSE | K188: FALSE | L188: FALSE | M188: FALSE | N188: FALSE | O188: No inspection
...

Sheet NEW Flexiloos
A1: Category | B1: Description | C1: Plant number | D1: Size | E1: Quantity | F1: Ply Cutting | G1: Cutting Sunmica | H1: Gluing Sunmica | I1: Groves for Hinges | J1: Ply frame assy | K1: Cutting Alu. Frame | L1: Assembly | M1: WC Fitting | N1: Vanity fitting | O1: Lighting | P1: Door frame | Q1: Door panel | R1: Snags | S1: TESTING | T1: Completion Date | U1: Comments
A2: Sanitation | B2: Flexiloo WC | C2: FLX.WC.87 | D2: Toilet | E2: 1 | F2: TRUE | G2: TRUE | H2: TRUE | I2: TRUE | J2: TRUE | K2: TRUE | L2: TRUE | M2: TRUE | N2: x | O2: TRUE | P2: TRUE | Q2: TRUE | R2: FALSE | S2: TRUE | T2: 45866
A3: Sanitation | B3: Flexiloo WC | C3: FLX.WC.88 | D3: Toilet | E3: 2 | F3: TRUE | G3: TRUE | H3: TRUE | I3: TRUE | J3: TRUE | K3: TRUE | L3: TRUE | M3: TRUE | N3: x | O3: TRUE | P3: TRUE | Q3: TRUE | R3: FALSE | S3: TRUE | T3: 45866
A4: Sanitation | B4: Flexiloo WC | C4: FLX.WC.89 | D4: Toilet | E4: 3 | F4: TRUE | G4: TRUE | H4: TRUE | I4: TRUE | J4: TRUE | K4: TRUE | L4: TRUE | M4: TRUE | N4: x | O4: TRUE | P4: TRUE | Q4: TRUE | R4: FALSE | S4: TRUE | T4: 45875
A5: Sanitation | B5: Flexiloo WC | C5: FLX.WC.90 | D5: Toilet | E5: 4 | F5: TRUE | G5: TRUE | H5: TRUE | I5: TRUE | J5: TRUE | K5: TRUE | L5: TRUE | M5: TRUE | N5: x | O5: TRUE | P5: TRUE | Q5: TRUE | R5: FALSE | S5: TRUE | T5: 45875
A6: Sanitation | B6: Flexiloo WC | C6: FLX.WC.91 | D6: Toilet | E6: 5 | F6: TRUE | G6: TRUE | H6: TRUE | I6: TRUE | J6: TRUE | K6: TRUE | L6: TRUE | M6: TRUE | N6: x | O6: TRUE | P6: TRUE | Q6: TRUE | R6: FALSE | S6: TRUE | T6: 45880
A7: Sanitation | B7: Flexiloo WC | C7: FLX.WC.92 | D7: Toilet | E7: 6 | F7: TRUE | G7: TRUE | H7: TRUE | I7: TRUE | J7: TRUE | K7: TRUE | L7: TRUE | M7: TRUE | N7: x | O7: TRUE | P7: TRUE | Q7: TRUE | R7: FALSE | S7: TRUE | T7: 45880
A8: Sanitation | B8: Flexiloo WC | C8: FLX.WC.93 | D8: Toilet | E8: 7 | F8: TRUE | G8: TRUE | H8: TRUE | I8: TRUE | J8: TRUE | K8: TRUE | L8: TRUE | M8: TRUE | N8: x | O8: TRUE | P8: TRUE | Q8: TRUE | R8: FALSE | S8: TRUE | T8: 45883
A9: Sanitation | B9: Flexiloo WC | C9: FLX.WC.94 | D9: Toilet | E9: 8 | F9: TRUE | G9: TRUE | H9: TRUE | I9: TRUE | J9: TRUE | K9: TRUE | L9: TRUE | M9: TRUE | N9: x | O9: TRUE | P9: TRUE | Q9: TRUE | R9: FALSE | S9: TRUE | T9: 45883
A10: Sanitation | B10: Flexiloo WC | C10: FLX.WC.95 | D10: Toilet | E10: 9 | F10: TRUE | G10: TRUE | H10: TRUE | I10: TRUE | J10: TRUE | K10: TRUE | L10: TRUE | M10: TRUE | N10: x | O10: TRUE | P10: TRUE | Q10: TRUE | R10: FALSE | S10: TRUE
A11: Sanitation | B11: Flexiloo WC | C11: FLX.WC.96 | D11: Toilet | E11: 10 | F11: TRUE | G11: TRUE | H11: TRUE | I11: TRUE | J11: TRUE | K11: TRUE | L11: TRUE | M11: TRUE | N11: x | O11: TRUE | P11: TRUE | Q11: TRUE | R11: FALSE | S11: TRUE
A12: Sanitation | B12: Flexiloo WC | C12: FLX.WC.97 | D12: Toilet | E12: 11 | F12: TRUE | G12: TRUE | H12: TRUE | I12: TRUE | J12: TRUE | K12: TRUE | L12: TRUE | M12: TRUE | N12: x | O12: TRUE | P12: TRUE | Q12: TRUE | R12: FALSE | S12: TRUE
A13: Sanitation | B13: Flexiloo WC | C13: FLX.WC.98 | D13: Toilet | E13: 12 | F13: TRUE | G13: TRUE | H13: TRUE | I13: TRUE | J13: TRUE | K13: TRUE | L13: TRUE | M13: TRUE | N13: x | O13: TRUE | P13: TRUE | Q13: TRUE | R13: FALSE | S13: TRUE
A14: Sanitation | B14: Flexiloo WC | C14: FLX.WC.99 | D14: Toilet | E14: 13 | F14: TRUE | G14: TRUE | H14: TRUE | I14: TRUE | J14: TRUE | K14: TRUE | L14: TRUE | M14: TRUE | N14: x | O14: TRUE | P14: TRUE | Q14: TRUE | R14: FALSE | S14: TRUE
A15: Sanitation | B15: Flexiloo WC | C15: FLX.WC.100 | D15: Toilet | E15: 14 | F15: TRUE | G15: TRUE | H15: TRUE | I15: TRUE | J15: TRUE | K15: TRUE | L15: TRUE | M15: TRUE | N15: x | O15: TRUE | P15: TRUE | Q15: TRUE | R15: FALSE | S15: TRUE
A16: Sanitation | B16: Flexiloo WC | C16: FLX.WC.101 | D16: Toilet | E16: 15 | F16: TRUE | G16: TRUE | H16: TRUE | I16: TRUE | J16: TRUE | K16: TRUE | L16: TRUE | M16: TRUE | N16: x | O16: TRUE | P16: TRUE | Q16: TRUE | R16: FALSE | S16: TRUE
A17: Sanitation | B17: Flexiloo WC | C17: FLX.WC.102 | D17: Toilet | E17: 16 | F17: TRUE | G17: TRUE | H17: TRUE | I17: TRUE | J17: TRUE | K17: TRUE | L17: TRUE | M17: TRUE | N17: x | O17: TRUE | P17: TRUE | Q17: TRUE | R17: FALSE | S17: TRUE
A18: Sanitation | B18: Flexiloo WC | C18: FLX.WC.103 | D18: Toilet | E18: 17 | F18: TRUE | G18: TRUE | H18: TRUE | I18: TRUE | J18: TRUE | K18: TRUE | L18: TRUE | M18: TRUE | N18: x | O18: TRUE | P18: TRUE | Q18: TRUE | R18: FALSE | S18: TRUE
A19: Sanitation | B19: Flexiloo WC | C19: FLX.WC.104 | D19: Toilet | E19: 18 | F19: TRUE | G19: TRUE | H19: TRUE | I19: TRUE | J19: TRUE | K19: TRUE | L19: TRUE | M19: TRUE | N19: x | O19: TRUE | P19: TRUE | Q19: TRUE | R19: FALSE | S19: TRUE
A20: Sanitation | B20: Flexiloo WC | C20: FLX.WC.105 | D20: Toilet | E20: 19 | F20: TRUE | G20: TRUE | H20: TRUE | I20: TRUE | J20: TRUE | K20: TRUE | L20: TRUE | M20: TRUE | N20: x | O20: TRUE | P20: TRUE | Q20: TRUE | R20: FALSE | S20: TRUE
A21: Sanitation | B21: Flexiloo WC | C21: FLX.WC.106 | D21: Toilet | E21: 20 | F21: TRUE | G21: TRUE | H21: TRUE | I21: TRUE | J21: TRUE | K21: TRUE | L21: TRUE | M21: TRUE | N21: x | O21: TRUE | P21: TRUE | Q21: TRUE | R21: FALSE | S21: TRUE
... A46: Sanitation | B46: Flexiloo WC | C46: FLX.WC.131 | D46: Toilet | E46: 45 | F46: FALSE | G46: FALSE | H46: FALSE | I46: FALSE | J46: FALSE | K46: FALSE | L46: FALSE | M46: FALSE | N46: x | O46: FALSE | P46: FALSE | Q46: FALSE | R46: FALSE | S46: FALSE
A47: Sanitation | B47: Flexiloo WC | C47: FLX.WC.132 | D47: Toilet | E47: 46 | F47: FALSE | G47: FALSE | H47: FALSE | I47: FALSE | J47: FALSE | K47: FALSE | L47: FALSE | M47: FALSE | N47: FALSE | O47: FALSE | P47: FALSE | Q47: FALSE | R47: FALSE | S47: FALSE
A48: Sanitation | B48: Flexiloo WC | C48: FLX.WC.133 | D48: Toilet | E48: 47 | F48: FALSE | G48: FALSE | H48: FALSE | I48: FALSE | J48: FALSE | K48: FALSE | L48: FALSE | M48: FALSE | N48: FALSE | O48: FALSE | P48: FALSE | Q48: FALSE | R48: FALSE | S48: FALSE
A49: Sanitation | B49: Flexiloo WC | C49: FLX.WC.134 | D49: Toilet | E49: 48 | F49: FALSE | G49: FALSE | H49: FALSE | I49: FALSE | J49: FALSE | K49: FALSE | L49: FALSE | M49: FALSE | N49: FALSE | O49: FALSE | P49: FALSE | Q49: FALSE | R49: FALSE | S49: FALSE
A50: Sanitation | B50: Flexiloo WC | C50: FLX.WC.135 | D50: Toilet | E50: 49 | F50: FALSE | G50: FALSE | H50: FALSE | I50: FALSE | J50: FALSE | K50: FALSE | L50: FALSE | M50: FALSE | N50: FALSE | O50: FALSE | P50: FALSE | Q50: FALSE | R50: FALSE | S50: FALSE
A51: Sanitation | B51: Flexiloo WC | C51: FLX.WC.136 | D51: Toilet | E51: 50 | F51: FALSE | G51: FALSE | H51: FALSE | I51: FALSE | J51: FALSE | K51: FALSE | L51: FALSE | M51: FALSE | N51: FALSE | O51: FALSE | P51: FALSE | Q51: FALSE | R51: FALSE | S51: FALSE
A52: Sanitation | B52: Flexiloo WC | C52: FLX.WC.137 | D52: Toilet | E52: 51 | F52: FALSE | G52: FALSE | H52: FALSE | I52: FALSE | J52: FALSE | K52: FALSE | L52: FALSE | M52: FALSE | N52: FALSE | O52: FALSE | P52: FALSE | Q52: FALSE | R52: FALSE | S52: FALSE
A53: Sanitation | B53: Flexiloo WC | C53: FLX.WC.138 | D53: Toilet | E53: FALSE | F53: FALSE | G53: FALSE | H53: FALSE | I53: FALSE | J53: FALSE | K53: FALSE | L53: FALSE | M53: FALSE | N53: FALSE | O53: FALSE | P53: FALSE | Q53: FALSE | R53: FALSE | S53: FALSE
A55: Sanitation | B55: Flexiloo Gent Urinal | C55: FLX.UR.054 | D55: Urinal | E55: 1 | F55: FALSE | G55: FALSE | H55: FALSE | I55: x | J55: FALSE | K55: FALSE | L55: FALSE | M55: x | N55: x | O55: FALSE | P55: x | Q55: x | R55: FALSE | S55: FALSE
A56: Sanitation | B56: Flexiloo Gent Urinal | C56: FLX.UR.055 | D56: Urinal | E56: 2 | F56: FALSE | G56: FALSE | H56: FALSE | I56: x | J56: FALSE | K56: FALSE | L56: FALSE | M56: x | N56: x | O56: FALSE | P56: x | Q56: x | R56: FALSE | S56: FALSE
A57: Sanitation | B57: Flexiloo Gent Urinal | C57: FLX.UR.056 | D57: Urinal | E57: 3 | F57: FALSE | G57: FALSE | H57: FALSE | I57: x | J57: FALSE | K57: FALSE | L57: FALSE | M57: x | N57: x | O57: FALSE | P57: x | Q57: x | R57: FALSE | S57: FALSE
A58: Sanitation | B58: Flexiloo Gent Urinal | C58: FLX.UR.057 | D58: Urinal | E58: 4 | F58: FALSE | G58: FALSE | H58: FALSE | I58: x | J58: FALSE | K58: FALSE | L58: FALSE | M58: x | N58: x | O58: FALSE | P58: x | Q58: x | R58: FALSE | S58: FALSE
A59: Sanitation | B59: Flexiloo Gent Urinal | C59: FLX.UR.058 | D59: Urinal | E59: 5 | F59: FALSE | G59: FALSE | H59: FALSE | I59: x | J59: FALSE | K59: FALSE | L59: FALSE | M59: x | N59: x | O59: FALSE | P59: x | Q59: x | R59: FALSE | S59: FALSE
A60: Sanitation | B60: Flexiloo Gent Urinal | C60: FLX.UR.059 | D60: Urinal | E60: 6 | F60: FALSE | G60: FALSE | H60: FALSE | I60: x | J60: FALSE | K60: FALSE | L60: FALSE | M60: x | N60: x | O60: FALSE | P60: x | Q60: x | R60: FALSE | S60: FALSE
A61: Sanitation | B61: Flexiloo Gent Urinal | C61: FLX.UR.060 | D61: Urinal | E61: 7 | F61: FALSE | G61: FALSE | H61: FALSE | I61: x | J61: FALSE | K61: FALSE | L61: FALSE | M61: x | N61: x | O61: FALSE | P61: x | Q61: x | R61: FALSE | S61: FALSE
A62: Sanitation | B62: Flexiloo Gent Urinal | C62: FLX.UR.061 | D62: Urinal | E62: 8 | F62: FALSE | G62: FALSE | H62: FALSE | I62: x | J62: FALSE | K62: FALSE | L62: FALSE | M62: x | N62: x | O62: FALSE | P62: x | Q62: x | R62: FALSE | S62: FALSE
A63: Sanitation | B63: Flexiloo Gent Urinal | C63: FLX.UR.062 | D63: Urinal | E63: 9 | F63: FALSE | G63: FALSE | H63: FALSE | I63: x | J63: FALSE | K63: FALSE | L63: FALSE | M63: x | N63: x | O63: FALSE | P63: x | Q63: x | R63: FALSE | S63: FALSE
A64: Sanitation | B64: Flexiloo Gent Urinal | C64: FLX.UR.063 | D64: Urinal | E64: 10 | F64: FALSE | G64: FALSE | H64: FALSE | I64: x | J64: FALSE | K64: FALSE | L64: FALSE | M64: x | N64: x | O64: FALSE | P64: x | Q64: x | R64: FALSE | S64: FALSE
A65: Sanitation | B65: Flexiloo Gent Urinal | C65: FLX.UR.064 | D65: Urinal | E65: 11 | F65: FALSE | G65: FALSE | H65: FALSE | I65: x | J65: FALSE | K65: FALSE | L65: FALSE | M65: x | N65: x | O65: FALSE | P65: x | Q65: x | R65: FALSE | S65: FALSE
...

Sheet Portaloo
A1: Category | B1: Spec | C1: Type | D1: Plant No. | E1: Interior fittings | F1: Flush lever | G1: Door lock | H1: Branding | I1: Comments
A2: Portaloo | B2: Disabled Portaloo | C2: Portaloo | D2: DA.PL.57 | E2: FALSE | F2: FALSE | G2: FALSE | H2: FALSE | I2: No inspection
A3: Portaloo | B3: Disabled Portaloo | C3: Portaloo | D3: DA.PL.58 | E3: FALSE | F3: FALSE | G3: FALSE | H3: FALSE | I3: No inspection
A4: Portaloo | B4: Portaloo | C4: Portaloo | D4: PL.03 | E4: TRUE | F4: TRUE | G4: TRUE | H4: FALSE | I4: [2026-03-30] Inpection done by Anto | By: Anto
A5: Portaloo | B5: Portaloo | C5: Portaloo | D5: PL.09 | E5: FALSE | F5: FALSE | G5: FALSE | H5: FALSE | I5: No inspection
A6: Portaloo | B6: Portaloo | C6: Portaloo | D6: PL.100 | E6: FALSE | F6: FALSE | G6: FALSE | H6: FALSE | I6: No inspection
A7: Portaloo | B7: Portaloo | C7: Portaloo | D7: PL.101 | E7: FALSE | F7: FALSE | G7: FALSE | H7: FALSE | I7: No inspection
A8: Portaloo | B8: Portaloo | C8: Portaloo | D8: PL.102 | E8: FALSE | F8: FALSE | G8: FALSE | H8: FALSE | I8: No inspection
A9: Portaloo | B9: Portaloo | C9: Portaloo | D9: PL.105 | E9: FALSE | F9: FALSE | G9: FALSE | H9: FALSE | I9: No inspection
A10: Portaloo | B10: Portaloo | C10: Portaloo | D10: PL.106 | E10: FALSE | F10: FALSE | G10: FALSE | H10: FALSE | I10: No inspection
A11: Portaloo | B11: Portaloo | C11: Portaloo | D11: PL.107 | E11: TRUE | F11: TRUE | G11: TRUE | H11: FALSE | I11: [2026-03-30] | By: calo.lategan@allaith.com
A12: Portaloo | B12: Portaloo | C12: Portaloo | D12: PL.108 | E12: FALSE | F12: FALSE | G12: FALSE | H12: FALSE | I12: No inspection
A13: Portaloo | B13: Portaloo | C13: Portaloo | D13: PL.109 | E13: FALSE | F13: FALSE | G13: FALSE | H13: FALSE | I13: No inspection
... A109: Portaloo | B109: Portaloo | C109: Portaloo | D109: PL.99 | E109: FALSE | F109: FALSE | G109: FALSE | H109: FALSE | I109: No inspection

Sheet Ezgo
A1: TYPE | B1: BRAND | C1: SPEC | D1: PLANT NO. | E1: PARTS ORDERED | F1: PARTS RECEIVED | G1: PARTS INSTALLED | H1: TYRES | I1: BATTERIES | J1: BRAKE CABLE ASSY | K1: BRAKE DRUM | L1: SPRING BUSH | M1: SPEED SENSOR | N1: HEAD LIGHT ASSY | O1: HORN SWITCH | P1: STEERING BOX ASSY | Q1: WINDSHIELD | R1: ACCELERATOR PEDAL ASSY | S1: FRONT BUMPER | T1: HORN | U1: KINGPIN | V1: FRONT ARM BUSH | W1: REAR AXLE | X1: TOW HITCH | Y1: MUD GUARD LH | Z1: FRONT BUMPER GUARD | AA1: CANOPY | AB1: BATTERY CABLE | AC1: TELEMATICS | AD1: POLISH | AE1: COMMENTS
A2: Golf Buggy | B2: EZGO - Abdullah | C2: 4 seater | D2: GB.4.112 | E2: FALSE | F2: FALSE | G2: FALSE | AC2: FALSE | AD2: FALSE
A3: Golf Buggy | B3: EZGO - Security | C3: 4 seater | D3: GB.4.118 | E3: FALSE | F3: FALSE | G3: FALSE | AC3: FALSE | AD3: FALSE
A4: Golf Buggy | B4: EZGO - Gold | C4: 4 seater | D4: GB.4.82 | E4: TRUE | F4: FALSE | G4: FALSE | O4: 1 | T4: 1 | AC4: FALSE | AD4: FALSE
A5: Golf Buggy | B5: Golf Buggy - Carryall 700 | C5: Van | D5: CAB.01 | E5: FALSE | F5: FALSE | G5: FALSE | AC5: FALSE | AD5: FALSE
A6: Golf Buggy | B6: Golf Buggy - Carryall 700 | C6: Van | D6: CAB.02 | E6: FALSE | F6: FALSE | G6: FALSE | AC6: FALSE | AD6: FALSE
A7: Golf Buggy | B7: EZGO | C7: 4 seater | D7: GB.4.10 | E7: TRUE | F7: FALSE | G7: FALSE | J7: 1 | L7: 4 | AC7: FALSE | AD7: FALSE
A8: Golf Buggy | B8: EZGO | C8: 4 seater | D8: GB.4.11 | E8: TRUE | F8: FALSE | G8: FALSE | K8: 2 | N8: 1 | AC8: FALSE | AD8: FALSE
A9: Golf Buggy | B9: EZGO | C9: 4 seater | D9: GB.4.113 | E9: TRUE | F9: FALSE | G9: FALSE | L9: 4 NO | Q9: 1 NO | S9: 1 NO | AC9: FALSE | AD9: FALSE
A10: Golf Buggy | B10: EZGO | C10: 4 seater | D10: GB.4.114 | E10: TRUE | F10: FALSE | G10: FALSE | M10: 1 NO | AC10: FALSE | AD10: FALSE
A11: Golf Buggy | B11: EZGO | C11: 4 seater | D11: GB.4.119 | E11: FALSE | F11: FALSE | G11: FALSE | AC11: FALSE | AD11: FALSE
A12: Golf Buggy | B12: EZGO | C12: 4 seater | D12: GB.4.12 | E12: TRUE | F12: FALSE | G12: FALSE | L12: 4 | O12: 1 | P12: 1 | Q12: 1 | AC12: FALSE | AD12: FALSE
A13: Golf Buggy | B13: EZGO | C13: 4 seater | D13: GB.4.122 | E13: FALSE | F13: FALSE | G13: FALSE | AC13: FALSE | AD13: FALSE
A14: Golf Buggy | B14: EZGO | C14: 4 seater | D14: GB.4.128 | E14: FALSE | F14: FALSE | G14: FALSE | AC14: FALSE | AD14: FALSE
A15: Golf Buggy | B15: EZGO | C15: 4 seater | D15: GB.4.129 | E15: FALSE | F15: FALSE | G15: FALSE | AC15: FALSE | AD15: FALSE
A16: Golf Buggy | B16: EZGO | C16: 4 seater | D16: GB.4.13 | E16: TRUE | F16: FALSE | G16: FALSE | Q16: 1 | R16: 1 | AC16: FALSE | AD16: FALSE
A17: Golf Buggy | B17: EZGO | C17: 4 seater | D17: GB.4.130 | E17: FALSE | F17: FALSE | G17: FALSE | AC17: FALSE | AD17: FALSE
A18: Golf Buggy | B18: EZGO | C18: 4 seater | D18: GB.4.132 | E18: FALSE | F18: FALSE | G18: FALSE | AC18: FALSE | AD18: FALSE
A19: Golf Buggy | B19: EZGO | C19: 4 seater | D19: GB.4.134 | E19: FALSE | F19: FALSE | G19: FALSE | AC19: FALSE | AD19: FALSE
A20: Golf Buggy | B20: EZGO | C20: 4 seater | D20: GB.4.139 | E20: FALSE | F20: FALSE | G20: FALSE | AC20: FALSE | AD20: FALSE
A21: Golf Buggy | B21: EZGO | C21: 4 seater | D21: GB.4.143 | E21: FALSE | F21: FALSE | G21: FALSE | AC21: FALSE | AD21: FALSE
A22: Golf Buggy | B22: EZGO | C22: 4 seater | D22: GB.4.144 | E22: FALSE | F22: FALSE | G22: FALSE | AC22: FALSE | AD22: FALSE
A23: Golf Buggy | B23: EZGO | C23: 4 seater | D23: GB.4.15 | E23: TRUE | F23: FALSE | G23: FALSE | L23: 4 | AC23: FALSE | AD23: FALSE
A24: Golf Buggy | B24: EZGO | C24: 4 seater | D24: GB.4.17 | E24: TRUE | F24: FALSE | G24: FALSE | L24: 4 | P24: 1 | Q24: 1 | S24: 1 | AC24: FALSE | AD24: FALSE
A25: Golf Buggy | B25: EZGO | C25: 4 seater | D25: GB.4.19 | E25: TRUE | F25: FALSE | G25: FALSE | Q25: 1 | AC25: FALSE | AD25: FALSE
A26: Golf Buggy | B26: EZGO | C26: 4 seater | D26: GB.4.27 | E26: FALSE | F26: FALSE | G26: FALSE | AC26: FALSE | AD26: FALSE
A27: Golf Buggy | B27: EZGO | C27: 4 seater | D27: GB.4.52 | E27: TRUE | F27: FALSE | G27: FALSE | L27: 4 | O27: 1 | Q27: 1 | S27: 1 | AC27: FALSE | AD27: FALSE
A28: Golf Buggy | B28: EZGO | C28: 4 seater | D28: GB.4.58 | E28: TRUE | F28: FALSE | G28: FALSE | L28: 4 | Q28: 1 | R28: 1 | AC28: FALSE | AD28: FALSE
A29: Golf Buggy | B29: EZGO | C29: 4 seater | D29: GB.4.59 | E29: TRUE | F29: FALSE | G29: FALSE | L29: 4 | O29: 1 | T29: 1 | AC29: FALSE | AD29: FALSE
A30: Golf Buggy | B30: EZGO | C30: 4 seater | D30: GB.4.60 | E30: TRUE | F30: FALSE | G30: FALSE | Q30: 1 | AC30: FALSE | AD30: FALSE
A31: Golf Buggy | B31: EZGO | C31: 4 seater | D31: GB.4.61 | E31: TRUE | F31: FALSE | G31: FALSE | S31: 1 | U31: 8 | AC31: FALSE | AD31: FALSE
A32: Golf Buggy | B32: EZGO | C32: 4 seater | D32: GB.4.62 | E32: TRUE | F32: FALSE | G32: FALSE | L32: 4 | O32: 1 | P32: 1 | T32: 1 | AC32: FALSE | AD32: FALSE
A33: Golf Buggy | B33: EZGO | C33: 4 seater | D33: GB.4.63 | E33: FALSE | F33: FALSE | G33: FALSE | AC33: FALSE | AD33: FALSE
A34: Golf Buggy | B34: EZGO | C34: 4 seater | D34: GB.4.64 | E34: TRUE | F34: FALSE | G34: FALSE | L34: 4 | O34: 1 | T34: 1 | AC34: FALSE | AD34: FALSE
A35: Golf Buggy | B35: EZGO | C35: 4 seater | D35: GB.4.65 | E35: TRUE | F35: FALSE | G35: FALSE | L35: 4 | O35: 1 | T35: 1 | U35: 8 | AB35: 5 | AC35: FALSE | AD35: FALSE
A36: Golf Buggy | B36: EZGO | C36: 4 seater | D36: GB.4.66 | E36: FALSE | F36: FALSE | G36: FALSE | AC36: FALSE | AD36: FALSE
A37: Golf Buggy | B37: EZGO | C37: 4 seater | D37: GB.4.67 | E37: TRUE | F37: FALSE | G37: FALSE | Q37: 1 | AA37: 1 | AC37: FALSE | AD37: FALSE
A38: Golf Buggy | B38: EZGO | C38: 4 seater | D38: GB.4.68 | E38: TRUE | F38: FALSE | G38: FALSE | L38: 4 | AC38: FALSE | AD38: FALSE
A39: Golf Buggy | B39: EZGO | C39: 4 seater | D39: GB.4.69 | E39: TRUE | F39: FALSE | G39: FALSE | L39: 4 | Q39: 1 | AC39: FALSE | AD39: FALSE
A40: Golf Buggy | B40: EZGO | C40: 4 seater | D40: GB.4.70 | E40: FALSE | F40: FALSE | G40: FALSE | AC40: FALSE | AD40: FALSE | AE40: Only labour charge on PO
...

Sheet Clubcar
A1: TYPE | B1: BRAND | C1: SPEC | D1: PLANT NO. | E1: INSPECTION June '23 | F1: PARTS ORDERED | G1: PARTS RECEIVED | H1: PARTS INSTALLED | I1: TYRES | J1: BATTERIES | K1: TELEMATICS | L1: POLISH | M1: COMMENTS
A2: Golf Buggy | B2: Club Car | C2: 4 seater | D2: GBC.4.145 | E2: TRUE | F2: FALSE | G2: FALSE | H2: FALSE | I2: FALSE | J2: FALSE | K2: FALSE | L2: FALSE
A3: Golf Buggy | B3: Club Car | C3: 4 seater | D3: GBC.4.146 | E3: TRUE | F3: FALSE | G3: FALSE | H3: FALSE | I3: FALSE | J3: FALSE | K3: FALSE | L3: FALSE
A4: Golf Buggy | B4: Club Car | C4: 4 seater | D4: GBC.4.147 | E4: TRUE | F4: FALSE | G4: FALSE | H4: FALSE | I4: FALSE | J4: FALSE | K4: FALSE | L4: FALSE
A5: Golf Buggy | B5: Club Car | C5: 4 seater | D5: GBC.4.148 | E5: TRUE | F5: FALSE | G5: FALSE | H5: FALSE | I5: FALSE | J5: FALSE | K5: FALSE | L5: FALSE
A6: Golf Buggy | B6: Club Car | C6: 4 seater | D6: GBC.4.149 | E6: TRUE | F6: FALSE | G6: FALSE | H6: FALSE | I6: FALSE | J6: FALSE | K6: FALSE | L6: FALSE
A7: Golf Buggy | B7: Club Car | C7: 4 seater | D7: GBC.4.150 | E7: TRUE | F7: FALSE | G7: FALSE | H7: FALSE | I7: FALSE | J7: FALSE | K7: FALSE | L7: FALSE
A8: Golf Buggy | B8: Club Car | C8: 4 seater | D8: GBC.4.151 | E8: TRUE | F8: FALSE | G8: FALSE | H8: FALSE | I8: FALSE | J8: FALSE | K8: FALSE | L8: FALSE
A9: Golf Buggy | B9: Club Car | C9: 4 seater | D9: GBC.4.152 | E9: TRUE | F9: FALSE | G9: FALSE | H9: FALSE | I9: FALSE | J9: FALSE | K9: FALSE | L9: FALSE
A10: Golf Buggy | B10: Club Car | C10: 4 seater | D10: GBC.4.153 | E10: TRUE | F10: FALSE | G10: FALSE | H10: FALSE | I10: FALSE | J10: FALSE | K10: FALSE | L10: FALSE
A11: Golf Buggy | B11: Club Car | C11: 4 seater | D11: GBC.4.154 | E11: TRUE | F11: FALSE | G11: FALSE | H11: FALSE | I11: FALSE | J11: FALSE | K11: FALSE | L11: FALSE
A12: Golf Buggy | B12: Club Car | C12: 4 seater | D12: GBC.4.155 | E12: TRUE | F12: FALSE | G12: FALSE | H12: FALSE | I12: FALSE | J12: FALSE | K12: FALSE | L12: FALSE
A13: Golf Buggy | B13: Club Car | C13: 4 seater | D13: GBC.4.156 | E13: TRUE | F13: FALSE | G13: FALSE | H13: FALSE | I13: FALSE | J13: FALSE | K13: FALSE | L13: FALSE
... A95: Golf Buggy | B95: Club Car | C95: 6 seater | D95: GBC.6.180 | E95: TRUE | F95: FALSE | G95: FALSE | H95: FALSE | I95: FALSE | J95: FALSE | K95: FALSE | L95: FALSE

Sheet Polaris
A1: Make | B1: Type | C1: Plant no. | D1: Problems | E1: Work to be done | F1: Cost
A2: Polaris | B2: Gator | C2: IRL.13
A3: Polaris | B3: Gator | C3: IRL.14
A4: Polaris | B4: Mule-ranger Crew M.s | C4: IRL.18
A5: Polaris | B5: Mule-ranger Crew F.s. | C5: IRL.20
A6: Polaris | B6: Mule-ranger Crew F.s. | C6: IRL.23
A7: Polaris | B7: Mule-ranger Crew M.s | C7: IRL.25
A8: Polaris | B8: Mule-ranger Crew M.s | C8: IRL.29
A9: Polaris | B9: Mule-ranger Crew M.s | C9: IRL.31
A10: Polaris | B10: Mule-ranger Crew M.s | C10: IRL.34
A11: Polaris | B11: Mule-ranger Crew M.s | C11: IRL.35
A12: Polaris | B12: Mule-ranger Crew M.s | C12: IRL.36
A13: Polaris | B13: Petrol Mule 2 Seater | C13: IRL.40
... A22: Polaris | B22: Electric Mule 2 Seater | C22: IRL.49

Sheet Kawasaki
A1: Kawasaki | B1: Gator | D1: IRL.01
A2: Kawasaki | B2: Gator | D2: IRL.02
